
# hanlde the exception in try..except 
# if successful: "the operation is successful".
# if fails: handle the specific exception and print a relevant message.

def additoin(x, y):
    try: 
        x = 10
        y = 20
        print("Addition:", x + b)
        print("the operation is successful")
    except NameError:
        print("please define variable b")

# find what type of exception is raised.
# NameError: name 'b' is not defined

additoin(10, 20)

